{
 "cells": [
  {
   "cell_type": "code",
   "execution_count": 1,
   "metadata": {
    "collapsed": false
   },
   "outputs": [],
   "source": [
    "import pyodbc\n",
    "import pandas as pd\n",
    "MY_DSN = \"DRIVER=/opt/mapr/drillodbc/lib/universal/libmaprdrillodbc.dylib;Host=localhost;Port=31010;ConnectionType=Direct;Catalog=Drill;Schema=mfs.views;AuthenticationType=No Authentication\"\n",
    "conn = pyodbc.connect(MY_DSN, autocommit=True, unicode_results=True)\n",
    "cursor = conn.cursor()"
   ]
  },
  {
   "cell_type": "code",
   "execution_count": 4,
   "metadata": {
    "collapsed": false
   },
   "outputs": [
    {
     "ename": "DatabaseError",
     "evalue": "Execution failed on sql 'SELECT * FROM cp.`employee.json`': ('HY000', '[HY000] [MapR][Drill] (1040) Drill failed to execute the query: ����������������\\n[30027]Query execution error. Details:[ \\nPARSE ERROR: Lexical error at line 1, column 1.  Encountered: \"\\\\ufffd\" (65533), after : \"\"\\n\\n\\n[Error Id: 37e6410e-7c24-4219-b5c3-5c377a2 (1040) (SQLExecDirectW)')",
     "output_type": "error",
     "traceback": [
      "\u001b[0;31m---------------------------------------------------------------------------\u001b[0m",
      "\u001b[0;31mError\u001b[0m                                     Traceback (most recent call last)",
      "\u001b[0;32m//anaconda/lib/python3.4/site-packages/pandas/io/sql.py\u001b[0m in \u001b[0;36mexecute\u001b[0;34m(self, *args, **kwargs)\u001b[0m\n\u001b[1;32m   1471\u001b[0m             \u001b[0;32melse\u001b[0m\u001b[0;34m:\u001b[0m\u001b[0;34m\u001b[0m\u001b[0m\n\u001b[0;32m-> 1472\u001b[0;31m                 \u001b[0mcur\u001b[0m\u001b[0;34m.\u001b[0m\u001b[0mexecute\u001b[0m\u001b[0;34m(\u001b[0m\u001b[0;34m*\u001b[0m\u001b[0margs\u001b[0m\u001b[0;34m)\u001b[0m\u001b[0;34m\u001b[0m\u001b[0m\n\u001b[0m\u001b[1;32m   1473\u001b[0m             \u001b[0;32mreturn\u001b[0m \u001b[0mcur\u001b[0m\u001b[0;34m\u001b[0m\u001b[0m\n",
      "\u001b[0;31mError\u001b[0m: ('HY000', '[HY000] [MapR][Drill] (1040) Drill failed to execute the query: ����������������\\n[30027]Query execution error. Details:[ \\nPARSE ERROR: Lexical error at line 1, column 1.  Encountered: \"\\\\ufffd\" (65533), after : \"\"\\n\\n\\n[Error Id: 37e6410e-7c24-4219-b5c3-5c377a2 (1040) (SQLExecDirectW)')",
      "\nDuring handling of the above exception, another exception occurred:\n",
      "\u001b[0;31mDatabaseError\u001b[0m                             Traceback (most recent call last)",
      "\u001b[0;32m<ipython-input-4-d07e8583dc9c>\u001b[0m in \u001b[0;36m<module>\u001b[0;34m()\u001b[0m\n\u001b[1;32m      9\u001b[0m \u001b[0memployee_query\u001b[0m \u001b[0;34m=\u001b[0m \u001b[0;34mu\"SELECT * FROM cp.`employee.json`\"\u001b[0m\u001b[0;34m\u001b[0m\u001b[0m\n\u001b[1;32m     10\u001b[0m \u001b[0;34m\u001b[0m\u001b[0m\n\u001b[0;32m---> 11\u001b[0;31m \u001b[0mdata\u001b[0m \u001b[0;34m=\u001b[0m \u001b[0mpd\u001b[0m\u001b[0;34m.\u001b[0m\u001b[0mread_sql\u001b[0m\u001b[0;34m(\u001b[0m \u001b[0memployee_query\u001b[0m\u001b[0;34m,\u001b[0m \u001b[0mconn\u001b[0m \u001b[0;34m)\u001b[0m\u001b[0;34m\u001b[0m\u001b[0m\n\u001b[0m",
      "\u001b[0;32m//anaconda/lib/python3.4/site-packages/pandas/io/sql.py\u001b[0m in \u001b[0;36mread_sql\u001b[0;34m(sql, con, index_col, coerce_float, params, parse_dates, columns, chunksize)\u001b[0m\n\u001b[1;32m    476\u001b[0m             \u001b[0msql\u001b[0m\u001b[0;34m,\u001b[0m \u001b[0mindex_col\u001b[0m\u001b[0;34m=\u001b[0m\u001b[0mindex_col\u001b[0m\u001b[0;34m,\u001b[0m \u001b[0mparams\u001b[0m\u001b[0;34m=\u001b[0m\u001b[0mparams\u001b[0m\u001b[0;34m,\u001b[0m\u001b[0;34m\u001b[0m\u001b[0m\n\u001b[1;32m    477\u001b[0m             \u001b[0mcoerce_float\u001b[0m\u001b[0;34m=\u001b[0m\u001b[0mcoerce_float\u001b[0m\u001b[0;34m,\u001b[0m \u001b[0mparse_dates\u001b[0m\u001b[0;34m=\u001b[0m\u001b[0mparse_dates\u001b[0m\u001b[0;34m,\u001b[0m\u001b[0;34m\u001b[0m\u001b[0m\n\u001b[0;32m--> 478\u001b[0;31m             chunksize=chunksize)\n\u001b[0m\u001b[1;32m    479\u001b[0m \u001b[0;34m\u001b[0m\u001b[0m\n\u001b[1;32m    480\u001b[0m     \u001b[0;32mtry\u001b[0m\u001b[0;34m:\u001b[0m\u001b[0;34m\u001b[0m\u001b[0m\n",
      "\u001b[0;32m//anaconda/lib/python3.4/site-packages/pandas/io/sql.py\u001b[0m in \u001b[0;36mread_query\u001b[0;34m(self, sql, index_col, coerce_float, params, parse_dates, chunksize)\u001b[0m\n\u001b[1;32m   1502\u001b[0m \u001b[0;34m\u001b[0m\u001b[0m\n\u001b[1;32m   1503\u001b[0m         \u001b[0margs\u001b[0m \u001b[0;34m=\u001b[0m \u001b[0m_convert_params\u001b[0m\u001b[0;34m(\u001b[0m\u001b[0msql\u001b[0m\u001b[0;34m,\u001b[0m \u001b[0mparams\u001b[0m\u001b[0;34m)\u001b[0m\u001b[0;34m\u001b[0m\u001b[0m\n\u001b[0;32m-> 1504\u001b[0;31m         \u001b[0mcursor\u001b[0m \u001b[0;34m=\u001b[0m \u001b[0mself\u001b[0m\u001b[0;34m.\u001b[0m\u001b[0mexecute\u001b[0m\u001b[0;34m(\u001b[0m\u001b[0;34m*\u001b[0m\u001b[0margs\u001b[0m\u001b[0;34m)\u001b[0m\u001b[0;34m\u001b[0m\u001b[0m\n\u001b[0m\u001b[1;32m   1505\u001b[0m         \u001b[0mcolumns\u001b[0m \u001b[0;34m=\u001b[0m \u001b[0;34m[\u001b[0m\u001b[0mcol_desc\u001b[0m\u001b[0;34m[\u001b[0m\u001b[0;36m0\u001b[0m\u001b[0;34m]\u001b[0m \u001b[0;32mfor\u001b[0m \u001b[0mcol_desc\u001b[0m \u001b[0;32min\u001b[0m \u001b[0mcursor\u001b[0m\u001b[0;34m.\u001b[0m\u001b[0mdescription\u001b[0m\u001b[0;34m]\u001b[0m\u001b[0;34m\u001b[0m\u001b[0m\n\u001b[1;32m   1506\u001b[0m \u001b[0;34m\u001b[0m\u001b[0m\n",
      "\u001b[0;32m//anaconda/lib/python3.4/site-packages/pandas/io/sql.py\u001b[0m in \u001b[0;36mexecute\u001b[0;34m(self, *args, **kwargs)\u001b[0m\n\u001b[1;32m   1481\u001b[0m \u001b[0;34m\u001b[0m\u001b[0m\n\u001b[1;32m   1482\u001b[0m             \u001b[0mex\u001b[0m \u001b[0;34m=\u001b[0m \u001b[0mDatabaseError\u001b[0m\u001b[0;34m(\u001b[0m\u001b[0;34m\"Execution failed on sql '%s': %s\"\u001b[0m \u001b[0;34m%\u001b[0m \u001b[0;34m(\u001b[0m\u001b[0margs\u001b[0m\u001b[0;34m[\u001b[0m\u001b[0;36m0\u001b[0m\u001b[0;34m]\u001b[0m\u001b[0;34m,\u001b[0m \u001b[0mexc\u001b[0m\u001b[0;34m)\u001b[0m\u001b[0;34m)\u001b[0m\u001b[0;34m\u001b[0m\u001b[0m\n\u001b[0;32m-> 1483\u001b[0;31m             \u001b[0mraise_with_traceback\u001b[0m\u001b[0;34m(\u001b[0m\u001b[0mex\u001b[0m\u001b[0;34m)\u001b[0m\u001b[0;34m\u001b[0m\u001b[0m\n\u001b[0m\u001b[1;32m   1484\u001b[0m \u001b[0;34m\u001b[0m\u001b[0m\n\u001b[1;32m   1485\u001b[0m     \u001b[0;34m@\u001b[0m\u001b[0mstaticmethod\u001b[0m\u001b[0;34m\u001b[0m\u001b[0m\n",
      "\u001b[0;32m//anaconda/lib/python3.4/site-packages/pandas/compat/__init__.py\u001b[0m in \u001b[0;36mraise_with_traceback\u001b[0;34m(exc, traceback)\u001b[0m\n\u001b[1;32m    706\u001b[0m         \u001b[0;32mif\u001b[0m \u001b[0mtraceback\u001b[0m \u001b[0;34m==\u001b[0m \u001b[0mEllipsis\u001b[0m\u001b[0;34m:\u001b[0m\u001b[0;34m\u001b[0m\u001b[0m\n\u001b[1;32m    707\u001b[0m             \u001b[0m_\u001b[0m\u001b[0;34m,\u001b[0m \u001b[0m_\u001b[0m\u001b[0;34m,\u001b[0m \u001b[0mtraceback\u001b[0m \u001b[0;34m=\u001b[0m \u001b[0msys\u001b[0m\u001b[0;34m.\u001b[0m\u001b[0mexc_info\u001b[0m\u001b[0;34m(\u001b[0m\u001b[0;34m)\u001b[0m\u001b[0;34m\u001b[0m\u001b[0m\n\u001b[0;32m--> 708\u001b[0;31m         \u001b[0;32mraise\u001b[0m \u001b[0mexc\u001b[0m\u001b[0;34m.\u001b[0m\u001b[0mwith_traceback\u001b[0m\u001b[0;34m(\u001b[0m\u001b[0mtraceback\u001b[0m\u001b[0;34m)\u001b[0m\u001b[0;34m\u001b[0m\u001b[0m\n\u001b[0m\u001b[1;32m    709\u001b[0m \u001b[0;32melse\u001b[0m\u001b[0;34m:\u001b[0m\u001b[0;34m\u001b[0m\u001b[0m\n\u001b[1;32m    710\u001b[0m     \u001b[0;31m# this version of raise is a syntax error in Python 3\u001b[0m\u001b[0;34m\u001b[0m\u001b[0;34m\u001b[0m\u001b[0m\n",
      "\u001b[0;32m//anaconda/lib/python3.4/site-packages/pandas/io/sql.py\u001b[0m in \u001b[0;36mexecute\u001b[0;34m(self, *args, **kwargs)\u001b[0m\n\u001b[1;32m   1470\u001b[0m                 \u001b[0mcur\u001b[0m\u001b[0;34m.\u001b[0m\u001b[0mexecute\u001b[0m\u001b[0;34m(\u001b[0m\u001b[0;34m*\u001b[0m\u001b[0margs\u001b[0m\u001b[0;34m,\u001b[0m \u001b[0;34m**\u001b[0m\u001b[0mkwargs\u001b[0m\u001b[0;34m)\u001b[0m\u001b[0;34m\u001b[0m\u001b[0m\n\u001b[1;32m   1471\u001b[0m             \u001b[0;32melse\u001b[0m\u001b[0;34m:\u001b[0m\u001b[0;34m\u001b[0m\u001b[0m\n\u001b[0;32m-> 1472\u001b[0;31m                 \u001b[0mcur\u001b[0m\u001b[0;34m.\u001b[0m\u001b[0mexecute\u001b[0m\u001b[0;34m(\u001b[0m\u001b[0;34m*\u001b[0m\u001b[0margs\u001b[0m\u001b[0;34m)\u001b[0m\u001b[0;34m\u001b[0m\u001b[0m\n\u001b[0m\u001b[1;32m   1473\u001b[0m             \u001b[0;32mreturn\u001b[0m \u001b[0mcur\u001b[0m\u001b[0;34m\u001b[0m\u001b[0m\n\u001b[1;32m   1474\u001b[0m         \u001b[0;32mexcept\u001b[0m \u001b[0mException\u001b[0m \u001b[0;32mas\u001b[0m \u001b[0mexc\u001b[0m\u001b[0;34m:\u001b[0m\u001b[0;34m\u001b[0m\u001b[0m\n",
      "\u001b[0;31mDatabaseError\u001b[0m: Execution failed on sql 'SELECT * FROM cp.`employee.json`': ('HY000', '[HY000] [MapR][Drill] (1040) Drill failed to execute the query: ����������������\\n[30027]Query execution error. Details:[ \\nPARSE ERROR: Lexical error at line 1, column 1.  Encountered: \"\\\\ufffd\" (65533), after : \"\"\\n\\n\\n[Error Id: 37e6410e-7c24-4219-b5c3-5c377a2 (1040) (SQLExecDirectW)')"
     ]
    }
   ],
   "source": [
    "\n",
    "#employee_query = \"\"\"SELECT position_title, COUNT( employee_id ) as employee_count\n",
    "#FROM cp.`employee.json`\n",
    "#GROUP BY position_title \n",
    "#\"\"\"\n",
    "\n",
    "#cursor.execute( 'use cp')\n",
    "\n",
    "employee_query = \"SELECT * FROM cp.`employee.json`\"\n",
    "\n",
    "data = pd.read_sql( employee_query, conn )\n"
   ]
  },
  {
   "cell_type": "code",
   "execution_count": null,
   "metadata": {
    "collapsed": true
   },
   "outputs": [],
   "source": []
  },
  {
   "cell_type": "code",
   "execution_count": null,
   "metadata": {
    "collapsed": true
   },
   "outputs": [],
   "source": []
  },
  {
   "cell_type": "code",
   "execution_count": null,
   "metadata": {
    "collapsed": true
   },
   "outputs": [],
   "source": []
  }
 ],
 "metadata": {
  "kernelspec": {
   "display_name": "Python 3",
   "language": "python",
   "name": "python3"
  },
  "language_info": {
   "codemirror_mode": {
    "name": "ipython",
    "version": 3
   },
   "file_extension": ".py",
   "mimetype": "text/x-python",
   "name": "python",
   "nbconvert_exporter": "python",
   "pygments_lexer": "ipython3",
   "version": "3.4.3"
  }
 },
 "nbformat": 4,
 "nbformat_minor": 0
}
